Workbook

Sheet Assumptions_Parameters
A1: Parameter | B1: Value | C1: Description
A2: Opening cash as of January 1, 2024 | B2: Rp 12.000.000 | C2: Kedai Renjana's cash balance before the 24-month historical period began. Starting point for calculating running cash.
A3: Current coffee bean price (Dec 2025) | B3: Rp 185.000 / kg | C3: Purchase price from the main supplier, valid to date.
A4: Estimated coffee bean price increase | B4: 10% - 20% | C4: Info from supplier, no definite figure yet. Kirana asked to simulate several scenarios at once (10%, 15%, 20%).
A5: Proportion of Raw Material cost from coffee beans | B5: 55% | C5: The remainder (45%) is milk, sugar, packaging, and other light food ingredients - prices are assumed to be relatively stable and not increasing.
A6: Minimum target cash reserve | B6: Not yet determined | C6: Kirana doesn't have a definite figure yet. She once heard the SME rule of thumb 'cash reserve = 3-6 months of fixed operating costs (Rent+Salary)' but hasn't decided which to use. To be discussed before moving on to Business Question no. 4-6.
A7: Capex Location C (near Station) - Rental deposit | B7: Rp 54.000.000 | C7: 1 year rental deposit paid in advance.
A8: Capex Location C (near Station) - Renovation & interior | B8: Rp 35.000.000
A9: Capex Location C (near Station) - Equipment | B9: Rp 45.000.000 | C9: Espresso machine, grinder, fridge, etc.
A10: Monthly rent Location C (year 2 onward) | B10: Rp 5.500.000 / bulan | C10: Outside the first 12-month projection horizon, recorded for reference.
A11: Capex Location D (near Residential area) - Rental deposit | B11: Rp 30.000.000 | C11: 1 year rental deposit paid in advance.
A12: Capex Location D (near Residential area) - Renovation & interior | B12: Rp 22.000.000
A13: Capex Location D (near Residential area) - Equipment | B13: Rp 40.000.000 | C13: Espresso machine, grinder, fridge, etc.
A14: Monthly rent Location D (year 2 onward) | B14: Rp 3.800.000 / bulan
A15: Revenue ramp-up Location C (from mature similar outlet revenue) | B15: Month 1: 50%, Month 2: 65%, Month 3: 78%, Month 4: 88%, Month 5: 95%, Month 6+: 100% | C15: Busy/high-traffic location but tight competition, fast ramp-up but with a plateau.
A16: Revenue ramp-up Location D (from mature similar outlet revenue) | B16: Month 1: 30%, Month 2: 42%, Month 3: 55%, Month 4: 68%, Month 5: 80%, Month 6: 90%, Month 7+: 100% | C16: Residential location, slow at first due to low awareness, steady upward trend (loyal community).
A17: Reference revenue of mature similar outlet (ramp-up basis) | B17: Average monthly revenue of Renjana Kedua over the last 6 months of historical data | C17: Used as the 100% basis in the ramp-up curve above - calculated from Fact_Penjualan_Harian data, not a fixed figure.
A18: Estimated monthly operating cost of new outlet once mature (excluding Rent & Raw Materials) | B18: Rp 5.800.000 / bulan | C18: Staff salary, utilities, routine marketing, etc. - average from Renjana Kedua's non-Rent non-Raw-Material cost pattern.
A19: Monthly organic growth rate of existing outlets (Kirana's expectation) | B19: 1% - 1.5% / bulan | C19: Kirana's own rough expectation - compare against the actual growth rate calculated from historical data.

Sheet Outlet_Reference
A1: outlet_id | B1: name | C1: location | D1: type | E1: start_operation_date | F1: area_m2 | G1: seating_capacity | H1: notes
A2: OUT01 | B2: Renjana Utama | C2: Jl. Perkantoran Sudirman (office area) | D2: Existing | E2: 2022-06-15 | F2: 45 | G2: 24 | H2: First outlet, targets office workers, busy hours weekday midday & afternoon
A3: OUT02 | B3: Renjana Kedua | C3: Jl. Kampus Merdeka (near campus) | D3: Existing | E3: 2024-04-01 | F3: 30 | G3: 18 | H3: Second outlet, targets students, busy on weekends & evenings, quiet during semester breaks
A4: CAND01 | B4: Lokasi C - Dekat Stasiun | C4: Area Stasiun Cikini Baru (fictional) | D4: Candidate | E4: TBD | F4: 25 | G4: 15 | H4: High traffic but tight competition (many other coffee shops within 200m radius)
A5: CAND02 | B5: Lokasi D - Dekat Perumahan | C5: Komplek Perumahan Graha Asri (fictional) | D5: Candidate | E5: TBD | F5: 35 | G5: 20 | H5: Minimal competitors, targets loyal community around the residential area, slower growth at the start

Sheet Daily_Sales
A1: Date | B1: Outlet | C1: Transaction_Count | D1: Revenue | E1: Month | F1: Day
A2: 45383 | B2: Renjana Kedua | C2: 18 | D2: 493000 | E2: =TEXT(A2,"yyyy-mm") -> 2024-04 | F2: =TEXT(A2,"ddd") -> Mon
A3: 45384 | B3: Renjana Kedua | C3: 24 | D3: 464000 | E3: =TEXT(A3,"yyyy-mm") -> 2024-04 | F3: =TEXT(A3,"ddd") -> Tue | I3: Sum of Omzet | J3: Column Labels
A4: 45385 | B4: Renjana Kedua | C4: 18 | D4: 474000 | E4: =TEXT(A4,"yyyy-mm") -> 2024-04 | F4: =TEXT(A4,"ddd") -> Wed | I4: Row Labels | J4: Renjana Kedua | K4: Renjana Utama | L4: Grand Total
A5: 45386 | B5: Renjana Kedua | C5: 7 | D5: 145000 | E5: =TEXT(A5,"yyyy-mm") -> 2024-04 | F5: =TEXT(A5,"ddd") -> Thu | I5: 2024-01 | K5: 23311000 | L5: 23311000
A6: 45387 | B6: Renjana Kedua | C6: 11 | D6: 229000 | E6: =TEXT(A6,"yyyy-mm") -> 2024-04 | F6: =TEXT(A6,"ddd") -> Fri | I6: 2024-02 | K6: 21807000 | L6: 21807000
A7: 45388 | B7: Renjana Kedua | C7: 15 | D7: 299000 | E7: =TEXT(A7,"yyyy-mm") -> 2024-04 | F7: =TEXT(A7,"ddd") -> Sat | I7: 2024-03 | K7: 23568000 | L7: 23568000
A8: 45389 | B8: Renjana Kedua | C8: 15 | D8: 263000 | E8: =TEXT(A8,"yyyy-mm") -> 2024-04 | F8: =TEXT(A8,"ddd") -> Sun | I8: 2024-04 | J8: 7934000 | K8: 21618000 | L8: 29552000
A9: 45390 | B9: Renjana Kedua | C9: 11 | D9: 216000 | E9: =TEXT(A9,"yyyy-mm") -> 2024-04 | F9: =TEXT(A9,"ddd") -> Mon | I9: 2024-05 | J9: 9698000 | K9: 24497000 | L9: 34195000
A10: 45391 | B10: Renjana Kedua | C10: 11 | D10: 208000 | E10: =TEXT(A10,"yyyy-mm") -> 2024-04 | F10: =TEXT(A10,"ddd") -> Tue | I10: 2024-06 | J10: 11495000 | K10: 24032000 | L10: 35527000
A11: 45392 | B11: Renjana Kedua | C11: 7 | D11: 193000 | E11: =TEXT(A11,"yyyy-mm") -> 2024-04 | F11: =TEXT(A11,"ddd") -> Wed | I11: 2024-07 | J11: 7654000 | K11: 25994000 | L11: 33648000
A12: 45393 | B12: Renjana Kedua | C12: 11 | D12: 227000 | E12: =TEXT(A12,"yyyy-mm") -> 2024-04 | F12: =TEXT(A12,"ddd") -> Thu | I12: 2024-08 | J12: 16359000 | K12: 20348000 | L12: 36707000
A13: 45394 | B13: Renjana Kedua | C13: 10 | D13: 202000 | E13: =TEXT(A13,"yyyy-mm") -> 2024-04 | F13: =TEXT(A13,"ddd") -> Fri | I13: 2024-09 | J13: 17983000 | K13: 25277000 | L13: 43260000
A14: 45395 | B14: Renjana Kedua | C14: 14 | D14: 278000 | E14: =TEXT(A14,"yyyy-mm") -> 2024-04 | F14: =TEXT(A14,"ddd") -> Sat | I14: 2024-10 | J14: 19908000 | K14: 27126000 | L14: 47034000
A15: 45396 | B15: Renjana Kedua | C15: 14 | D15: 268000 | E15: =TEXT(A15,"yyyy-mm") -> 2024-04 | F15: =TEXT(A15,"ddd") -> Sun | I15: 2024-11 | J15: 19575000 | K15: 26274000 | L15: 45849000
A16: 45397 | B16: Renjana Kedua | C16: 12 | D16: 224000 | E16: =TEXT(A16,"yyyy-mm") -> 2024-04 | F16: =TEXT(A16,"ddd") -> Mon | I16: 2024-12 | J16: 19798000 | K16: 33596000 | L16: 53394000
A17: 45398 | B17: Renjana Kedua | C17: 11 | D17: 214000 | E17: =TEXT(A17,"yyyy-mm") -> 2024-04 | F17: =TEXT(A17,"ddd") -> Tue | I17: 2025-01 | J17: 14331000 | K17: 28787000 | L17: 43118000
A18: 45399 | B18: Renjana Kedua | C18: 10 | D18: 230000 | E18: =TEXT(A18,"yyyy-mm") -> 2024-04 | F18: =TEXT(A18,"ddd") -> Wed | I18: 2025-02 | J18: 18588000 | K18: 26023000 | L18: 44611000
A19: 45400 | B19: Renjana Kedua | C19: 10 | D19: 207000 | E19: =TEXT(A19,"yyyy-mm") -> 2024-04 | F19: =TEXT(A19,"ddd") -> Thu | I19: 2025-03 | J19: 21933000 | K19: 28568000 | L19: 50501000
... A29: 45410 | B29: Renjana Kedua | C29: 13 | D29: 276000 | E29: =TEXT(A29,"yyyy-mm") -> 2024-04 | F29: =TEXT(A29,"ddd") -> Sun | I29: Grand Total | J29: 372849000 | K29: 664856000 | L29: 1037705000
A30: 45411 | B30: Renjana Kedua | C30: 10 | D30: 201000 | E30: =TEXT(A30,"yyyy-mm") -> 2024-04 | F30: =TEXT(A30,"ddd") -> Mon
A31: 45412 | B31: Renjana Kedua | C31: 9 | D31: 208000 | E31: =TEXT(A31,"yyyy-mm") -> 2024-04 | F31: =TEXT(A31,"ddd") -> Tue
A32: 45413 | B32: Renjana Kedua | C32: 14 | D32: 268000 | E32: =TEXT(A32,"yyyy-mm") -> 2024-05 | F32: =TEXT(A32,"ddd") -> Wed
A33: 45414 | B33: Renjana Kedua | C33: 12 | D33: 253000 | E33: =TEXT(A33,"yyyy-mm") -> 2024-05 | F33: =TEXT(A33,"ddd") -> Thu
A34: 45415 | B34: Renjana Kedua | C34: 12 | D34: 278000 | E34: =TEXT(A34,"yyyy-mm") -> 2024-05 | F34: =TEXT(A34,"ddd") -> Fri
A35: 45416 | B35: Renjana Kedua | C35: 17 | D35: 372000 | E35: =TEXT(A35,"yyyy-mm") -> 2024-05 | F35: =TEXT(A35,"ddd") -> Sat
A36: 45417 | B36: Renjana Kedua | C36: 17 | D36: 357000 | E36: =TEXT(A36,"yyyy-mm") -> 2024-05 | F36: =TEXT(A36,"ddd") -> Sun
A37: 45418 | B37: Renjana Kedua | C37: 12 | D37: 265000 | E37: =TEXT(A37,"yyyy-mm") -> 2024-05 | F37: =TEXT(A37,"ddd") -> Mon
A38: 45419 | B38: Renjana Kedua | C38: 17 | D38: 255000 | E38: =TEXT(A38,"yyyy-mm") -> 2024-05 | F38: =TEXT(A38,"ddd") -> Tue
A39: 45420 | B39: Renjana Kedua | C39: 12 | D39: 284000 | E39: =TEXT(A39,"yyyy-mm") -> 2024-05 | F39: =TEXT(A39,"ddd") -> Wed
A40: 45421 | B40: Renjana Kedua | C40: 12 | D40: 234000 | E40: =TEXT(A40,"yyyy-mm") -> 2024-05 | F40: =TEXT(A40,"ddd") -> Thu
A41: 45422 | B41: Renjana Kedua | C41: 14 | D41: 255000 | E41: =TEXT(A41,"yyyy-mm") -> 2024-05 | F41: =TEXT(A41,"ddd") -> Fri
... A830: 45480 | B830: Renjana Utama | C830: 20 | D830: 542000 | E830: =TEXT(A830,"yyyy-mm") -> 2024-07 | F830: =TEXT(A830,"ddd") -> Sun
A831: 45481 | B831: Renjana Utama | D831: 919000 | E831: =TEXT(A831,"yyyy-mm") -> 2024-07 | F831: =TEXT(A831,"ddd") -> Mon
A832: 45482 | B832: Renjana Utama | D832: 868000 | E832: =TEXT(A832,"yyyy-mm") -> 2024-07 | F832: =TEXT(A832,"ddd") -> Tue
A833: 45483 | B833: Renjana Utama | D833: 1006000 | E833: =TEXT(A833,"yyyy-mm") -> 2024-07 | F833: =TEXT(A833,"ddd") -> Wed
A834: 45484 | B834: Renjana Utama | D834: 985000 | E834: =TEXT(A834,"yyyy-mm") -> 2024-07 | F834: =TEXT(A834,"ddd") -> Thu
A835: 45485 | B835: Renjana Utama | D835: 686000 | E835: =TEXT(A835,"yyyy-mm") -> 2024-07 | F835: =TEXT(A835,"ddd") -> Fri
A836: 45486 | B836: Renjana Utama | C836: 25 | D836: 634000 | E836: =TEXT(A836,"yyyy-mm") -> 2024-07 | F836: =TEXT(A836,"ddd") -> Sat
A837: 45487 | B837: Renjana Utama | C837: 21 | D837: 540000 | E837: =TEXT(A837,"yyyy-mm") -> 2024-07 | F837: =TEXT(A837,"ddd") -> Sun
...

Sheet Monthly_Costs
A1: Month | B1: Outlet | C1: Cost_Category | D1: Amount | G1: Kategori_biaya | H1: Sewa | L1: Kategori_biaya | M1: Bahan Baku
A2: 2024-01 | B2: Renjana Utama | C2: Raw Materials | D2: 7178000
A3: 2024-01 | B3: Renjana Utama | C3: Salary | D3: 6000000 | G3: Sum of Jumlah | H3: Column Labels | L3: Row Labels | M3: Sum of Jumlah
A4: 2024-01 | B4: Renjana Utama | C4: Rent | D4: 4000000 | G4: Row Labels | H4: Renjana Kedua | I4: Renjana Utama | J4: Grand Total | L4: Renjana Kedua | M4: 123419000
A5: 2024-01 | B5: Renjana Utama | C5: Utilities | D5: 742000 | G5: 2024-01 | I5: 4000000 | J5: 4000000 | L5: Renjana Utama | M5: 214960000
A6: 2024-01 | B6: Renjana Utama | C6: Marketing | D6: 400000 | G6: 2024-02 | I6: 4000000 | J6: 4000000 | L6: Grand Total | M6: 338379000
A7: 2024-01 | B7: Renjana Utama | C7: Maintenance | D7: 0 | G7: 2024-03 | I7: 4000000 | J7: 4000000
A8: 2024-01 | B8: Renjana Utama | C8: Other | D8: 354000 | G8: 2024-04 | H8: 3000000 | I8: 4000000 | J8: 7000000
A9: 2024-02 | B9: Renjana Utama | C9: Raw Materials | D9: 7251000 | G9: 2024-05 | H9: 3000000 | I9: 4000000 | J9: 7000000
A10: 2024-02 | B10: Renjana Utama | C10: Salary | D10: 6000000 | G10: 2024-06 | H10: 3000000 | I10: 4000000 | J10: 7000000
A11: 2024-02 | B11: Renjana Utama | C11: Rent | D11: 4000000 | G11: 2024-07 | H11: 3000000 | I11: 4000000 | J11: 7000000
A12: 2024-02 | B12: Renjana Utama | C12: Utilities | D12: 867000 | G12: 2024-08 | H12: 3000000 | I12: 4000000 | J12: 7000000
A13: 2024-02 | B13: Renjana Utama | C13: Marketing | D13: 700000 | G13: 2024-09 | H13: 3000000 | I13: 4000000 | J13: 7000000
A14: 2024-02 | B14: Renjana Utama | C14: Maintenance | D14: 0 | G14: 2024-10 | H14: 3000000 | I14: 4000000 | J14: 7000000
A15: 2024-02 | B15: Renjana Utama | C15: Other | D15: 328000 | G15: 2024-11 | H15: 3000000 | I15: 4000000 | J15: 7000000
A16: 2024-03 | B16: Renjana Utama | C16: Raw Materials | D16: 7565000 | G16: 2024-12 | H16: 3000000 | I16: 4000000 | J16: 7000000
A17: 2024-03 | B17: Renjana Utama | C17: Salary | D17: 6000000 | G17: 2025-01 | H17: 3000000 | I17: 4000000 | J17: 7000000
A18: 2024-03 | B18: Renjana Utama | C18: Rent | D18: 4000000 | G18: 2025-02 | H18: 3000000 | I18: 4000000 | J18: 7000000
A19: 2024-03 | B19: Renjana Utama | C19: Utilities | D19: 740000 | G19: 2025-03 | H19: 3000000 | I19: 4000000 | J19: 7000000
... A29: 2024-04 | B29: Renjana Utama | C29: Other | D29: 424000 | G29: Grand Total | H29: 63000000 | I29: 96000000 | J29: 159000000
A30: 2024-05 | B30: Renjana Utama | C30: Raw Materials | D30: 7997000
A31: 2024-05 | B31: Renjana Utama | C31: Salary | D31: 6000000
A32: 2024-05 | B32: Renjana Utama | C32: Rent | D32: 4000000
A33: 2024-05 | B33: Renjana Utama | C33: Utilities | D33: 834000
A34: 2024-05 | B34: Renjana Utama | C34: Marketing | D34: 400000
A35: 2024-05 | B35: Renjana Utama | C35: Maintenance | D35: 300000
A36: 2024-05 | B36: Renjana Utama | C36: Other | D36: 292000
A37: 2024-06 | B37: Renjana Utama | C37: Raw Materials | D37: 8242000
A38: 2024-06 | B38: Renjana Utama | C38: Salary | D38: 6000000
A39: 2024-06 | B39: Renjana Utama | C39: Rent | D39: 4000000
A40: 2024-06 | B40: Renjana Utama | C40: Utilities | D40: 908000
A41: 2024-06 | B41: Renjana Utama | C41: Marketing | D41: 0
... A318: 2025-12 | B318: Renjana Kedua | C318: Other | D318: 395000

Sheet Projection
A1: Month | B1: Main Revenue | C1: Second Revenue | D1: Total Revenue | E1: Main Costs | F1: Second Costs | G1: Total Costs | H1: Margin | I1: Month-End Cash | J1: Main Margin | K1: Second Margin | M1: Growth Main Revenue (B14-B25) | N1: Growth Second Revenue (C17-C25) | O1: Growth Main Cost (E14-E25) | P1: Growth Second Cost (F17-F25)
A2: 45292 | B2: =SUMIFS(Daily_Sales!D:D,Daily_Sales!B:B,"Renjana Utama",Daily_Sales!E:E,TEXT(Projection!$A2,"yyyy-mm")) -> 23311000 | C2: =SUMIFS(Daily_Sales!D:D,Daily_Sales!B:B,"Renjana Kedua",Daily_Sales!E:E,TEXT(Projection!$A2,"yyyy-mm")) -> 0 | D2: =Projection!$B2+Projection!$C2 -> 23311000 | E2: =SUMIFS(Monthly_Costs!D:D,Monthly_Costs!B:B,"Renjana Utama",Monthly_Costs!A:A,TEXT(Projection!$A2,"yyyy-mm")) -> 18674000 | F2: =SUMIFS(Monthly_Costs!D:D,Monthly_Costs!B:B,"Renjana Kedua",Monthly_Costs!A:A,TEXT(Projection!$A2,"yyyy-mm")) -> 0 | G2: =Projection!$E2+Projection!$F2 -> 18674000 | H2: =Projection!$D2-Projection!$G2 -> 4637000 | I2: =12000000+Projection!$H2 -> 16637000 | J2: =Projection!$B2-Projection!$E2 -> 4637000 | K2: =Projection!$C2-Projection!$F2 -> 0 | M2: =B14/Projection!$B2-1 -> 0.23491056 | O2: =E14/Projection!$E2-1 -> 0.14833458
A3: =EDATE(A2,1) -> 45323 | B3: =SUMIFS(Daily_Sales!D:D,Daily_Sales!B:B,"Renjana Utama",Daily_Sales!E:E,TEXT(Projection!$A3,"yyyy-mm")) -> 21807000 | C3: =SUMIFS(Daily_Sales!D:D,Daily_Sales!B:B,"Renjana Kedua",Daily_Sales!E:E,TEXT(Projection!$A3,"yyyy-mm")) -> 0 | D3: =Projection!$B3+Projection!$C3 -> 21807000 | E3: =SUMIFS(Monthly_Costs!D:D,Monthly_Costs!B:B,"Renjana Utama",Monthly_Costs!A:A,TEXT(Projection!$A3,"yyyy-mm")) -> 19146000 | F3: =SUMIFS(Monthly_Costs!D:D,Monthly_Costs!B:B,"Renjana Kedua",Monthly_Costs!A:A,TEXT(Projection!$A3,"yyyy-mm")) -> 0 | G3: =Projection!$E3+Projection!$F3 -> 19146000 | H3: =Projection!$D3-Projection!$G3 -> 2661000 | I3: =I2+Projection!$H3 -> 19298000 | J3: =Projection!$B3-Projection!$E3 -> 2661000 | K3: =Projection!$C3-Projection!$F3 -> 0 | M3: =B15/Projection!$B3-1 -> 0.19333242 | O3: =E15/Projection!$E3-1 -> 0.092029667
A4: =EDATE(A3,1) -> 45352 | B4: =SUMIFS(Daily_Sales!D:D,Daily_Sales!B:B,"Renjana Utama",Daily_Sales!E:E,TEXT(Projection!$A4,"yyyy-mm")) -> 23568000 | C4: =SUMIFS(Daily_Sales!D:D,Daily_Sales!B:B,"Renjana Kedua",Daily_Sales!E:E,TEXT(Projection!$A4,"yyyy-mm")) -> 0 | D4: =Projection!$B4+Projection!$C4 -> 23568000 | E4: =SUMIFS(Monthly_Costs!D:D,Monthly_Costs!B:B,"Renjana Utama",Monthly_Costs!A:A,TEXT(Projection!$A4,"yyyy-mm")) -> 18731000 | F4: =SUMIFS(Monthly_Costs!D:D,Monthly_Costs!B:B,"Renjana Kedua",Monthly_Costs!A:A,TEXT(Projection!$A4,"yyyy-mm")) -> 0 | G4: =Projection!$E4+Projection!$F4 -> 18731000 | H4: =Projection!$D4-Projection!$G4 -> 4837000 | I4: =I3+Projection!$H4 -> 24135000 | J4: =Projection!$B4-Projection!$E4 -> 4837000 | K4: =Projection!$C4-Projection!$F4 -> 0 | M4: =B16/Projection!$B4-1 -> 0.21215207 | O4: =E16/Projection!$E4-1 -> 0.12748919
A5: =EDATE(A4,1) -> 45383 | B5: =SUMIFS(Daily_Sales!D:D,Daily_Sales!B:B,"Renjana Utama",Daily_Sales!E:E,TEXT(Projection!$A5,"yyyy-mm")) -> 21618000 | C5: =SUMIFS(Daily_Sales!D:D,Daily_Sales!B:B,"Renjana Kedua",Daily_Sales!E:E,TEXT(Projection!$A5,"yyyy-mm")) -> 7934000 | D5: =Projection!$B5+Projection!$C5 -> 29552000 | E5: =SUMIFS(Monthly_Costs!D:D,Monthly_Costs!B:B,"Renjana Utama",Monthly_Costs!A:A,TEXT(Projection!$A5,"yyyy-mm")) -> 17847000 | F5: =SUMIFS(Monthly_Costs!D:D,Monthly_Costs!B:B,"Renjana Kedua",Monthly_Costs!A:A,TEXT(Projection!$A5,"yyyy-mm")) -> 12342000 | G5: =Projection!$E5+Projection!$F5 -> 30189000 | H5: =Projection!$D5-Projection!$G5 -> -637000 | I5: =I4+Projection!$H5 -> 23498000 | J5: =Projection!$B5-Projection!$E5 -> 3771000 | K5: =Projection!$C5-Projection!$F5 -> -4408000 | M5: =B17/Projection!$B5-1 -> 0.29808493 | N5: =C17/C5-1 -> 1.5969246 | O5: =E17/Projection!$E5-1 -> 0.1970079 | P5: =F17/Projection!$F5-1 -> 0.29184897
A6: =EDATE(A5,1) -> 45413 | B6: =SUMIFS(Daily_Sales!D:D,Daily_Sales!B:B,"Renjana Utama",Daily_Sales!E:E,TEXT(Projection!$A6,"yyyy-mm")) -> 24497000 | C6: =SUMIFS(Daily_Sales!D:D,Daily_Sales!B:B,"Renjana Kedua",Daily_Sales!E:E,TEXT(Projection!$A6,"yyyy-mm")) -> 9698000 | D6: =Projection!$B6+Projection!$C6 -> 34195000 | E6: =SUMIFS(Monthly_Costs!D:D,Monthly_Costs!B:B,"Renjana Utama",Monthly_Costs!A:A,TEXT(Projection!$A6,"yyyy-mm")) -> 19823000 | F6: =SUMIFS(Monthly_Costs!D:D,Monthly_Costs!B:B,"Renjana Kedua",Monthly_Costs!A:A,TEXT(Projection!$A6,"yyyy-mm")) -> 12367000 | G6: =Projection!$E6+Projection!$F6 -> 32190000 | H6: =Projection!$D6-Projection!$G6 -> 2005000 | I6: =I5+Projection!$H6 -> 25503000 | J6: =Projection!$B6-Projection!$E6 -> 4674000 | K6: =Projection!$C6-Projection!$F6 -> -2669000 | M6: =B18/Projection!$B6-1 -> 0.22561946 | N6: =C18/C6-1 -> 1.184471 | O6: =E18/Projection!$E6-1 -> 0.170509 | P6: =F18/Projection!$F6-1 -> 0.42184847
A7: =EDATE(A6,1) -> 45444 | B7: =SUMIFS(Daily_Sales!D:D,Daily_Sales!B:B,"Renjana Utama",Daily_Sales!E:E,TEXT(Projection!$A7,"yyyy-mm")) -> 24032000 | C7: =SUMIFS(Daily_Sales!D:D,Daily_Sales!B:B,"Renjana Kedua",Daily_Sales!E:E,TEXT(Projection!$A7,"yyyy-mm")) -> 11495000 | D7: =Projection!$B7+Projection!$C7 -> 35527000 | E7: =SUMIFS(Monthly_Costs!D:D,Monthly_Costs!B:B,"Renjana Utama",Monthly_Costs!A:A,TEXT(Projection!$A7,"yyyy-mm")) -> 19435000 | F7: =SUMIFS(Monthly_Costs!D:D,Monthly_Costs!B:B,"Renjana Kedua",Monthly_Costs!A:A,TEXT(Projection!$A7,"yyyy-mm")) -> 13435000 | G7: =Projection!$E7+Projection!$F7 -> 32870000 | H7: =Projection!$D7-Projection!$G7 -> 2657000 | I7: =I6+Projection!$H7 -> 28160000 | J7: =Projection!$B7-Projection!$E7 -> 4597000 | K7: =Projection!$C7-Projection!$F7 -> -1940000 | M7: =B19/Projection!$B7-1 -> 0.24209387 | N7: =C19/C7-1 -> 0.82705524 | O7: =E19/Projection!$E7-1 -> 0.11031644 | P7: =F19/Projection!$F7-1 -> 0.19888351
A8: =EDATE(A7,1) -> 45474 | B8: =SUMIFS(Daily_Sales!D:D,Daily_Sales!B:B,"Renjana Utama",Daily_Sales!E:E,TEXT(Projection!$A8,"yyyy-mm")) -> 25994000 | C8: =SUMIFS(Daily_Sales!D:D,Daily_Sales!B:B,"Renjana Kedua",Daily_Sales!E:E,TEXT(Projection!$A8,"yyyy-mm")) -> 7654000 | D8: =Projection!$B8+Projection!$C8 -> 33648000 | E8: =SUMIFS(Monthly_Costs!D:D,Monthly_Costs!B:B,"Renjana Utama",Monthly_Costs!A:A,TEXT(Projection!$A8,"yyyy-mm")) -> 20791000 | F8: =SUMIFS(Monthly_Costs!D:D,Monthly_Costs!B:B,"Renjana Kedua",Monthly_Costs!A:A,TEXT(Projection!$A8,"yyyy-mm")) -> 11233000 | G8: =Projection!$E8+Projection!$F8 -> 32024000 | H8: =Projection!$D8-Projection!$G8 -> 1624000 | I8: =I7+Projection!$H8 -> 29784000 | J8: =Projection!$B8-Projection!$E8 -> 5203000 | K8: =Projection!$C8-Projection!$F8 -> -3579000 | M8: =B20/Projection!$B8-1 -> 0.20908671 | N8: =C20/C8-1 -> 0.60896263 | O8: =E20/Projection!$E8-1 -> 0.088980809 | P8: =F20/Projection!$F8-1 -> 0.17421882
A9: =EDATE(A8,1) -> 45505 | B9: =SUMIFS(Daily_Sales!D:D,Daily_Sales!B:B,"Renjana Utama",Daily_Sales!E:E,TEXT(Projection!$A9,"yyyy-mm")) -> 20348000 | C9: =SUMIFS(Daily_Sales!D:D,Daily_Sales!B:B,"Renjana Kedua",Daily_Sales!E:E,TEXT(Projection!$A9,"yyyy-mm")) -> 16359000 | D9: =Projection!$B9+Projection!$C9 -> 36707000 | E9: =SUMIFS(Monthly_Costs!D:D,Monthly_Costs!B:B,"Renjana Utama",Monthly_Costs!A:A,TEXT(Projection!$A9,"yyyy-mm")) -> 17555000 | F9: =SUMIFS(Monthly_Costs!D:D,Monthly_Costs!B:B,"Renjana Kedua",Monthly_Costs!A:A,TEXT(Projection!$A9,"yyyy-mm")) -> 13697000 | G9: =Projection!$E9+Projection!$F9 -> 31252000 | H9: =Projection!$D9-Projection!$G9 -> 5455000 | I9: =I8+Projection!$H9 -> 35239000 | J9: =Projection!$B9-Projection!$E9 -> 2793000 | K9: =Projection!$C9-Projection!$F9 -> 2662000 | M9: =B21/Projection!$B9-1 -> 0.50348929 | N9: =C21/C9-1 -> 0.35588972 | O9: =E21/Projection!$E9-1 -> 0.24107092 | P9: =F21/Projection!$F9-1 -> 0.19756151
A10: =EDATE(A9,1) -> 45536 | B10: =SUMIFS(Daily_Sales!D:D,Daily_Sales!B:B,"Renjana Utama",Daily_Sales!E:E,TEXT(Projection!$A10,"yyyy-mm")) -> 25277000 | C10: =SUMIFS(Daily_Sales!D:D,Daily_Sales!B:B,"Renjana Kedua",Daily_Sales!E:E,TEXT(Projection!$A10,"yyyy-mm")) -> 17983000 | D10: =Projection!$B10+Projection!$C10 -> 43260000 | E10: =SUMIFS(Monthly_Costs!D:D,Monthly_Costs!B:B,"Renjana Utama",Monthly_Costs!A:A,TEXT(Projection!$A10,"yyyy-mm")) -> 19754000 | F10: =SUMIFS(Monthly_Costs!D:D,Monthly_Costs!B:B,"Renjana Kedua",Monthly_Costs!A:A,TEXT(Projection!$A10,"yyyy-mm")) -> 14814000 | G10: =Projection!$E10+Projection!$F10 -> 34568000 | H10: =Projection!$D10-Projection!$G10 -> 8692000 | I10: =I9+Projection!$H10 -> 43931000 | J10: =Projection!$B10-Projection!$E10 -> 5523000 | K10: =Projection!$C10-Projection!$F10 -> 3169000 | M10: =B22/Projection!$B10-1 -> 0.25465839 | N10: =C22/C10-1 -> 0.20691764 | O10: =E22/Projection!$E10-1 -> 0.12989774 | P10: =F22/Projection!$F10-1 -> 0.17672472
A11: =EDATE(A10,1) -> 45566 | B11: =SUMIFS(Daily_Sales!D:D,Daily_Sales!B:B,"Renjana Utama",Daily_Sales!E:E,TEXT(Projection!$A11,"yyyy-mm")) -> 27126000 | C11: =SUMIFS(Daily_Sales!D:D,Daily_Sales!B:B,"Renjana Kedua",Daily_Sales!E:E,TEXT(Projection!$A11,"yyyy-mm")) -> 19908000 | D11: =Projection!$B11+Projection!$C11 -> 47034000 | E11: =SUMIFS(Monthly_Costs!D:D,Monthly_Costs!B:B,"Renjana Utama",Monthly_Costs!A:A,TEXT(Projection!$A11,"yyyy-mm")) -> 19896000 | F11: =SUMIFS(Monthly_Costs!D:D,Monthly_Costs!B:B,"Renjana Kedua",Monthly_Costs!A:A,TEXT(Projection!$A11,"yyyy-mm")) -> 14408000 | G11: =Projection!$E11+Projection!$F11 -> 34304000 | H11: =Projection!$D11-Projection!$G11 -> 12730000 | I11: =I10+Projection!$H11 -> 56661000 | J11: =Projection!$B11-Projection!$E11 -> 7230000 | K11: =Projection!$C11-Projection!$F11 -> 5500000 | M11: =B23/Projection!$B11-1 -> 0.17064809 | N11: =C23/C11-1 -> 0.14546916 | O11: =E23/Projection!$E11-1 -> 0.10685565 | P11: =F23/Projection!$F11-1 -> 0.12867851
A12: =EDATE(A11,1) -> 45597 | B12: =SUMIFS(Daily_Sales!D:D,Daily_Sales!B:B,"Renjana Utama",Daily_Sales!E:E,TEXT(Projection!$A12,"yyyy-mm")) -> 26274000 | C12: =SUMIFS(Daily_Sales!D:D,Daily_Sales!B:B,"Renjana Kedua",Daily_Sales!E:E,TEXT(Projection!$A12,"yyyy-mm")) -> 19575000 | D12: =Projection!$B12+Projection!$C12 -> 45849000 | E12: =SUMIFS(Monthly_Costs!D:D,Monthly_Costs!B:B,"Renjana Utama",Monthly_Costs!A:A,TEXT(Projection!$A12,"yyyy-mm")) -> 20331000 | F12: =SUMIFS(Monthly_Costs!D:D,Monthly_Costs!B:B,"Renjana Kedua",Monthly_Costs!A:A,TEXT(Projection!$A12,"yyyy-mm")) -> 15308000 | G12: =Projection!$E12+Projection!$F12 -> 35639000 | H12: =Projection!$D12-Projection!$G12 -> 10210000 | I12: =I11+Projection!$H12 -> 66871000 | J12: =Projection!$B12-Projection!$E12 -> 5943000 | K12: =Projection!$C12-Projection!$F12 -> 4267000 | M12: =B24/Projection!$B12-1 -> 0.16868387 | N12: =C24/C12-1 -> 0.1543295 | O12: =E24/Projection!$E12-1 -> 0.10019183 | P12: =F24/Projection!$F12-1 -> 0.033054612
A13: =EDATE(A12,1) -> 45627 | B13: =SUMIFS(Daily_Sales!D:D,Daily_Sales!B:B,"Renjana Utama",Daily_Sales!E:E,TEXT(Projection!$A13,"yyyy-mm")) -> 33596000 | C13: =SUMIFS(Daily_Sales!D:D,Daily_Sales!B:B,"Renjana Kedua",Daily_Sales!E:E,TEXT(Projection!$A13,"yyyy-mm")) -> 19798000 | D13: =Projection!$B13+Projection!$C13 -> 53394000 | E13: =SUMIFS(Monthly_Costs!D:D,Monthly_Costs!B:B,"Renjana Utama",Monthly_Costs!A:A,TEXT(Projection!$A13,"yyyy-mm")) -> 24525000 | F13: =SUMIFS(Monthly_Costs!D:D,Monthly_Costs!B:B,"Renjana Kedua",Monthly_Costs!A:A,TEXT(Projection!$A13,"yyyy-mm")) -> 15734000 | G13: =Projection!$E13+Projection!$F13 -> 40259000 | H13: =Projection!$D13-Projection!$G13 -> 13135000 | I13: =I12+Projection!$H13 -> 80006000 | J13: =Projection!$B13-Projection!$E13 -> 9071000 | K13: =Projection!$C13-Projection!$F13 -> 4064000 | M13: =B25/Projection!$B13-1 -> 0.18755209 | N13: =C25/C13-1 -> 0.17193656 | O13: =E25/Projection!$E13-1 -> 0.055535168 | P13: =F25/Projection!$F13-1 -> 0.10118215
A14: =EDATE(A13,1) -> 45658 | B14: =SUMIFS(Daily_Sales!D:D,Daily_Sales!B:B,"Renjana Utama",Daily_Sales!E:E,TEXT(Projection!$A14,"yyyy-mm")) -> 28787000 | C14: =SUMIFS(Daily_Sales!D:D,Daily_Sales!B:B,"Renjana Kedua",Daily_Sales!E:E,TEXT(Projection!$A14,"yyyy-mm")) -> 14331000 | D14: =Projection!$B14+Projection!$C14 -> 43118000 | E14: =SUMIFS(Monthly_Costs!D:D,Monthly_Costs!B:B,"Renjana Utama",Monthly_Costs!A:A,TEXT(Projection!$A14,"yyyy-mm")) -> 21444000 | F14: =SUMIFS(Monthly_Costs!D:D,Monthly_Costs!B:B,"Renjana Kedua",Monthly_Costs!A:A,TEXT(Projection!$A14,"yyyy-mm")) -> 13342000 | G14: =Projection!$E14+Projection!$F14 -> 34786000 | H14: =Projection!$D14-Projection!$G14 -> 8332000 | I14: =I13+Projection!$H14 -> 88338000 | J14: =Projection!$B14-Projection!$E14 -> 7343000 | K14: =Projection!$C14-Projection!$F14 -> 989000
A15: =EDATE(A14,1) -> 45689 | B15: =SUMIFS(Daily_Sales!D:D,Daily_Sales!B:B,"Renjana Utama",Daily_Sales!E:E,TEXT(Projection!$A15,"yyyy-mm")) -> 26023000 | C15: =SUMIFS(Daily_Sales!D:D,Daily_Sales!B:B,"Renjana Kedua",Daily_Sales!E:E,TEXT(Projection!$A15,"yyyy-mm")) -> 18588000 | D15: =Projection!$B15+Projection!$C15 -> 44611000 | E15: =SUMIFS(Monthly_Costs!D:D,Monthly_Costs!B:B,"Renjana Utama",Monthly_Costs!A:A,TEXT(Projection!$A15,"yyyy-mm")) -> 20908000 | F15: =SUMIFS(Monthly_Costs!D:D,Monthly_Costs!B:B,"Renjana Kedua",Monthly_Costs!A:A,TEXT(Projection!$A15,"yyyy-mm")) -> 15386000 | G15: =Projection!$E15+Projection!$F15 -> 36294000 | H15: =Projection!$D15-Projection!$G15 -> 8317000 | I15: =I14+Projection!$H15 -> 96655000 | J15: =Projection!$B15-Projection!$E15 -> 5115000 | K15: =Projection!$C15-Projection!$F15 -> 3202000 | M15: Avg Growth Main Revenue : | O15: =AVERAGE(M2:M13) -> 0.24169265
A16: =EDATE(A15,1) -> 45717 | B16: =SUMIFS(Daily_Sales!D:D,Daily_Sales!B:B,"Renjana Utama",Daily_Sales!E:E,TEXT(Projection!$A16,"yyyy-mm")) -> 28568000 | C16: =SUMIFS(Daily_Sales!D:D,Daily_Sales!B:B,"Renjana Kedua",Daily_Sales!E:E,TEXT(Projection!$A16,"yyyy-mm")) -> 21933000 | D16: =Projection!$B16+Projection!$C16 -> 50501000 | E16: =SUMIFS(Monthly_Costs!D:D,Monthly_Costs!B:B,"Renjana Utama",Monthly_Costs!A:A,TEXT(Projection!$A16,"yyyy-mm")) -> 21119000 | F16: =SUMIFS(Monthly_Costs!D:D,Monthly_Costs!B:B,"Renjana Kedua",Monthly_Costs!A:A,TEXT(Projection!$A16,"yyyy-mm")) -> 16283000 | G16: =Projection!$E16+Projection!$F16 -> 37402000 | H16: =Projection!$D16-Projection!$G16 -> 13099000 | I16: =I15+Projection!$H16 -> 109754000 | J16: =Projection!$B16-Projection!$E16 -> 7449000 | K16: =Projection!$C16-Projection!$F16 -> 5650000 | M16: Avg Growth Second Revenue : | O16: =AVERAGE(N10:N13) -> 0.16966322
A17: =EDATE(A16,1) -> 45748 | B17: =SUMIFS(Daily_Sales!D:D,Daily_Sales!B:B,"Renjana Utama",Daily_Sales!E:E,TEXT(Projection!$A17,"yyyy-mm")) -> 28062000 | C17: =SUMIFS(Daily_Sales!D:D,Daily_Sales!B:B,"Renjana Kedua",Daily_Sales!E:E,TEXT(Projection!$A17,"yyyy-mm")) -> 20604000 | D17: =Projection!$B17+Projection!$C17 -> 48666000 | E17: =SUMIFS(Monthly_Costs!D:D,Monthly_Costs!B:B,"Renjana Utama",Monthly_Costs!A:A,TEXT(Projection!$A17,"yyyy-mm")) -> 21363000 | F17: =SUMIFS(Monthly_Costs!D:D,Monthly_Costs!B:B,"Renjana Kedua",Monthly_Costs!A:A,TEXT(Projection!$A17,"yyyy-mm")) -> 15944000 | G17: =Projection!$E17+Projection!$F17 -> 37307000 | H17: =Projection!$D17-Projection!$G17 -> 11359000 | I17: =I16+Projection!$H17 -> 121113000 | J17: =Projection!$B17-Projection!$E17 -> 6699000 | K17: =Projection!$C17-Projection!$F17 -> 4660000 | M17: Avg Growth Main Cost : | O17: =AVERAGE(O2:O13) -> 0.13068491
A18: =EDATE(A17,1) -> 45778 | B18: =SUMIFS(Daily_Sales!D:D,Daily_Sales!B:B,"Renjana Utama",Daily_Sales!E:E,TEXT(Projection!$A18,"yyyy-mm")) -> 30024000 | C18: =SUMIFS(Daily_Sales!D:D,Daily_Sales!B:B,"Renjana Kedua",Daily_Sales!E:E,TEXT(Projection!$A18,"yyyy-mm")) -> 21185000 | D18: =Projection!$B18+Projection!$C18 -> 51209000 | E18: =SUMIFS(Monthly_Costs!D:D,Monthly_Costs!B:B,"Renjana Utama",Monthly_Costs!A:A,TEXT(Projection!$A18,"yyyy-mm")) -> 23203000 | F18: =SUMIFS(Monthly_Costs!D:D,Monthly_Costs!B:B,"Renjana Kedua",Monthly_Costs!A:A,TEXT(Projection!$A18,"yyyy-mm")) -> 17584000 | G18: =Projection!$E18+Projection!$F18 -> 40787000 | H18: =Projection!$D18-Projection!$G18 -> 10422000 | I18: =I17+Projection!$H18 -> 131535000 | J18: =Projection!$B18-Projection!$E18 -> 6821000 | K18: =Projection!$C18-Projection!$F18 -> 3601000 | M18: Avg Growth Second Cost : | O18: =AVERAGE(P10:P13) -> 0.10991
A19: =EDATE(A18,1) -> 45809 | B19: =SUMIFS(Daily_Sales!D:D,Daily_Sales!B:B,"Renjana Utama",Daily_Sales!E:E,TEXT(Projection!$A19,"yyyy-mm")) -> 29850000 | C19: =SUMIFS(Daily_Sales!D:D,Daily_Sales!B:B,"Renjana Kedua",Daily_Sales!E:E,TEXT(Projection!$A19,"yyyy-mm")) -> 21002000 | D19: =Projection!$B19+Projection!$C19 -> 50852000 | E19: =SUMIFS(Monthly_Costs!D:D,Monthly_Costs!B:B,"Renjana Utama",Monthly_Costs!A:A,TEXT(Projection!$A19,"yyyy-mm")) -> 21579000 | F19: =SUMIFS(Monthly_Costs!D:D,Monthly_Costs!B:B,"Renjana Kedua",Monthly_Costs!A:A,TEXT(Projection!$A19,"yyyy-mm")) -> 16107000 | G19: =Projection!$E19+Projection!$F19 -> 37686000 | H19: =Projection!$D19-Projection!$G19 -> 13166000 | I19: =I18+Projection!$H19 -> 144701000 | J19: =Projection!$B19-Projection!$E19 -> 8271000 | K19: =Projection!$C19-Projection!$F19 -> 4895000
A20: =EDATE(A19,1) -> 45839 | B20: =SUMIFS(Daily_Sales!D:D,Daily_Sales!B:B,"Renjana Utama",Daily_Sales!E:E,TEXT(Projection!$A20,"yyyy-mm")) -> 31429000 | C20: =SUMIFS(Daily_Sales!D:D,Daily_Sales!B:B,"Renjana Kedua",Daily_Sales!E:E,TEXT(Projection!$A20,"yyyy-mm")) -> 12315000 | D20: =Projection!$B20+Projection!$C20 -> 43744000 | E20: =SUMIFS(Monthly_Costs!D:D,Monthly_Costs!B:B,"Renjana Utama",Monthly_Costs!A:A,TEXT(Projection!$A20,"yyyy-mm")) -> 22641000 | F20: =SUMIFS(Monthly_Costs!D:D,Monthly_Costs!B:B,"Renjana Kedua",Monthly_Costs!A:A,TEXT(Projection!$A20,"yyyy-mm")) -> 13190000 | G20: =Projection!$E20+Projection!$F20 -> 35831000 | H20: =Projection!$D20-Projection!$G20 -> 7913000 | I20: =I19+Projection!$H20 -> 152614000 | J20: =Projection!$B20-Projection!$E20 -> 8788000 | K20: =Projection!$C20-Projection!$F20 -> -875000
A21: =EDATE(A20,1) -> 45870 | B21: =SUMIFS(Daily_Sales!D:D,Daily_Sales!B:B,"Renjana Utama",Daily_Sales!E:E,TEXT(Projection!$A21,"yyyy-mm")) -> 30593000 | C21: =SUMIFS(Daily_Sales!D:D,Daily_Sales!B:B,"Renjana Kedua",Daily_Sales!E:E,TEXT(Projection!$A21,"yyyy-mm")) -> 22181000 | D21: =Projection!$B21+Projection!$C21 -> 52774000 | E21: =SUMIFS(Monthly_Costs!D:D,Monthly_Costs!B:B,"Renjana Utama",Monthly_Costs!A:A,TEXT(Projection!$A21,"yyyy-mm")) -> 21787000 | F21: =SUMIFS(Monthly_Costs!D:D,Monthly_Costs!B:B,"Renjana Kedua",Monthly_Costs!A:A,TEXT(Projection!$A21,"yyyy-mm")) -> 16403000 | G21: =Projection!$E21+Projection!$F21 -> 38190000 | H21: =Projection!$D21-Projection!$G21 -> 14584000 | I21: =I20+Projection!$H21 -> 167198000 | J21: =Projection!$B21-Projection!$E21 -> 8806000 | K21: =Projection!$C21-Projection!$F21 -> 5778000
A22: =EDATE(A21,1) -> 45901 | B22: =SUMIFS(Daily_Sales!D:D,Daily_Sales!B:B,"Renjana Utama",Daily_Sales!E:E,TEXT(Projection!$A22,"yyyy-mm")) -> 31714000 | C22: =SUMIFS(Daily_Sales!D:D,Daily_Sales!B:B,"Renjana Kedua",Daily_Sales!E:E,TEXT(Projection!$A22,"yyyy-mm")) -> 21704000 | D22: =Projection!$B22+Projection!$C22 -> 53418000 | E22: =SUMIFS(Monthly_Costs!D:D,Monthly_Costs!B:B,"Renjana Utama",Monthly_Costs!A:A,TEXT(Projection!$A22,"yyyy-mm")) -> 22320000 | F22: =SUMIFS(Monthly_Costs!D:D,Monthly_Costs!B:B,"Renjana Kedua",Monthly_Costs!A:A,TEXT(Projection!$A22,"yyyy-mm")) -> 17432000 | G22: =Projection!$E22+Projection!$F22 -> 39752000 | H22: =Projection!$D22-Projection!$G22 -> 13666000 | I22: =I21+Projection!$H22 -> 180864000 | J22: =Projection!$B22-Projection!$E22 -> 9394000 | K22: =Projection!$C22-Projection!$F22 -> 4272000
A23: =EDATE(A22,1) -> 45931 | B23: =SUMIFS(Daily_Sales!D:D,Daily_Sales!B:B,"Renjana Utama",Daily_Sales!E:E,TEXT(Projection!$A23,"yyyy-mm")) -> 31755000 | C23: =SUMIFS(Daily_Sales!D:D,Daily_Sales!B:B,"Renjana Kedua",Daily_Sales!E:E,TEXT(Projection!$A23,"yyyy-mm")) -> 22804000 | D23: =Projection!$B23+Projection!$C23 -> 54559000 | E23: =SUMIFS(Monthly_Costs!D:D,Monthly_Costs!B:B,"Renjana Utama",Monthly_Costs!A:A,TEXT(Projection!$A23,"yyyy-mm")) -> 22022000 | F23: =SUMIFS(Monthly_Costs!D:D,Monthly_Costs!B:B,"Renjana Kedua",Monthly_Costs!A:A,TEXT(Projection!$A23,"yyyy-mm")) -> 16262000 | G23: =Projection!$E23+Projection!$F23 -> 38284000 | H23: =Projection!$D23-Projection!$G23 -> 16275000 | I23: =I22+Projection!$H23 -> 197139000 | J23: =Projection!$B23-Projection!$E23 -> 9733000 | K23: =Projection!$C23-Projection!$F23 -> 6542000
A24: =EDATE(A23,1) -> 45962 | B24: =SUMIFS(Daily_Sales!D:D,Daily_Sales!B:B,"Renjana Utama",Daily_Sales!E:E,TEXT(Projection!$A24,"yyyy-mm")) -> 30706000 | C24: =SUMIFS(Daily_Sales!D:D,Daily_Sales!B:B,"Renjana Kedua",Daily_Sales!E:E,TEXT(Projection!$A24,"yyyy-mm")) -> 22596000 | D24: =Projection!$B24+Projection!$C24 -> 53302000 | E24: =SUMIFS(Monthly_Costs!D:D,Monthly_Costs!B:B,"Renjana Utama",Monthly_Costs!A:A,TEXT(Projection!$A24,"yyyy-mm")) -> 22368000 | F24: =SUMIFS(Monthly_Costs!D:D,Monthly_Costs!B:B,"Renjana Kedua",Monthly_Costs!A:A,TEXT(Projection!$A24,"yyyy-mm")) -> 15814000 | G24: =Projection!$E24+Projection!$F24 -> 38182000 | H24: =Projection!$D24-Projection!$G24 -> 15120000 | I24: =I23+Projection!$H24 -> 212259000 | J24: =Projection!$B24-Projection!$E24 -> 8338000 | K24: =Projection!$C24-Projection!$F24 -> 6782000
A25: =EDATE(A24,1) -> 45992 | B25: =SUMIFS(Daily_Sales!D:D,Daily_Sales!B:B,"Renjana Utama",Daily_Sales!E:E,TEXT(Projection!$A25,"yyyy-mm")) -> 39897000 | C25: =SUMIFS(Daily_Sales!D:D,Daily_Sales!B:B,"Renjana Kedua",Daily_Sales!E:E,TEXT(Projection!$A25,"yyyy-mm")) -> 23202000 | D25: =Projection!$B25+Projection!$C25 -> 63099000 | E25: =SUMIFS(Monthly_Costs!D:D,Monthly_Costs!B:B,"Renjana Utama",Monthly_Costs!A:A,TEXT(Projection!$A25,"yyyy-mm")) -> 25887000 | F25: =SUMIFS(Monthly_Costs!D:D,Monthly_Costs!B:B,"Renjana Kedua",Monthly_Costs!A:A,TEXT(Projection!$A25,"yyyy-mm")) -> 17326000 | G25: =Projection!$E25+Projection!$F25 -> 43213000 | H25: =Projection!$D25-Projection!$G25 -> 19886000 | I25: =I24+Projection!$H25 -> 232145000 | J25: =Projection!$B25-Projection!$E25 -> 14010000 | K25: =Projection!$C25-Projection!$F25 -> 5876000
A27: 2026 | M27: % increase in coffee bean price : | O27: 0
A28: Month | B28: Main Revenue | C28: Second Revenue | D28: Total Revenue | E28: Main Costs | F28: Second Costs | G28: Total Costs | H28: Margin | I28: Month-End Cash | J28: Main Margin | K28: Second Margin | L28: Main Raw Materials | M28: Second Raw Materials | N28: Main Other Costs | O28: Second Other Costs | P28: Main Costs Final | Q28: Second Costs Final
A29: =EDATE(A25,1) -> 46023 | B29: =B14*(1+$O$15) -> 35744606 | C29: =C14*(1+$O$16) -> 16762444 | D29: =B29+C29 -> 52507050 | E29: =E14*(1+$O$17) -> 24246407 | F29: =F14*(1+$O$18) -> 14808419 | G29: =P29+Q29 -> 39054826 | H29: =D29-G29 -> 13452223 | I29: =I25+H29 -> 2.4559722e+08 | J29: =B29-P29 -> 11498199 | K29: =C29-Q29 -> 1954024.3 | L29: =B29*32.3% -> 11545508 | M29: =C29*33.1% -> 5548368.8 | N29: =E29-L29 -> 12700899 | O29: =F29-M29 -> 9260050.4 | P29: =N29 + L29*(1-55%) + L29*55%*(1+$O$27) -> 24246407 | Q29: =O29 + M29*(1-55%) + M29*55%*(1+$O$27) -> 14808419
A30: =EDATE(A29,1) -> 46054 | B30: =B15*(1+$O$15) -> 32312568 | C30: =C15*(1+$O$16) -> 21741700 | D30: =B30+C30 -> 54054268 | E30: =E15*(1+$O$17) -> 23640360 | F30: =F15*(1+$O$18) -> 17077075 | G30: =P30+Q30 -> 40717435 | H30: =D30-G30 -> 13336832 | I30: =I29+H30 -> 2.5893406e+08 | J30: =B30-P30 -> 8672207.6 | K30: =C30-Q30 -> 4664624.6 | L30: =B30*32.3% -> 10436959 | M30: =C30*33.1% -> 7196502.7 | N30: =E30-L30 -> 13203401 | O30: =F30-M30 -> 9880572.6 | P30: =N30 + L30*(1-55%) + L30*55%*(1+$O$27) -> 23640360 | Q30: =O30 + M30*(1-55%) + M30*55%*(1+$O$27) -> 17077075
A31: =EDATE(A30,1) -> 46082 | B31: =B16*(1+$O$15) -> 35472675 | C31: =C16*(1+$O$16) -> 25654223 | D31: =B31+C31 -> 61126899 | E31: =E16*(1+$O$17) -> 23878935 | F31: =F16*(1+$O$18) -> 18072665 | G31: =P31+Q31 -> 41951599 | H31: =D31-G31 -> 19175300 | I31: =I30+H31 -> 2.7810936e+08 | J31: =B31-P31 -> 11593741 | K31: =C31-Q31 -> 7581558.8 | L31: =B31*32.3% -> 11457674 | M31: =C31*33.1% -> 8491547.9 | N31: =E31-L31 -> 12421260 | O31: =F31-M31 -> 9581116.6 | P31: =N31 + L31*(1-55%) + L31*55%*(1+$O$27) -> 23878935 | Q31: =O31 + M31*(1-55%) + M31*55%*(1+$O$27) -> 18072665
A32: =EDATE(A31,1) -> 46113 | B32: =B17*(1+$O$15) -> 34844379 | C32: =C17*(1+$O$16) -> 24099741 | D32: =B32+C32 -> 58944120 | E32: =E17*(1+$O$17) -> 24154822 | F32: =F17*(1+$O$18) -> 17696405 | G32: =P32+Q32 -> 41851227 | H32: =D32-G32 -> 17092893 | I32: =I31+H32 -> 2.9520225e+08 | J32: =B32-P32 -> 10689557 | K32: =C32-Q32 -> 6403335.9 | L32: =B32*32.3% -> 11254734 | M32: =C32*33.1% -> 7977014.2 | N32: =E32-L32 -> 12900087 | O32: =F32-M32 -> 9719390.8 | P32: =N32 + L32*(1-55%) + L32*55%*(1+$O$27) -> 24154822 | Q32: =O32 + M32*(1-55%) + M32*55%*(1+$O$27) -> 17696405
A33: =EDATE(A32,1) -> 46143 | B33: =B18*(1+$O$15) -> 37280580 | C33: =C18*(1+$O$16) -> 24779315 | D33: =B33+C33 -> 62059895 | E33: =E18*(1+$O$17) -> 26235282 | F33: =F18*(1+$O$18) -> 19516657 | G33: =P33+Q33 -> 45751939 | H33: =D33-G33 -> 16307956 | I33: =I32+H33 -> 3.115102e+08 | J33: =B33-P33 -> 11045298 | K33: =C33-Q33 -> 5262657.8 | L33: =B33*32.3% -> 12041627 | M33: =C33*33.1% -> 8201953.3 | N33: =E33-L33 -> 14193655 | O33: =F33-M33 -> 11314704 | P33: =N33 + L33*(1-55%) + L33*55%*(1+$O$27) -> 26235282 | Q33: =O33 + M33*(1-55%) + M33*55%*(1+$O$27) -> 19516657
A34: =EDATE(A33,1) -> 46174 | B34: =B19*(1+$O$15) -> 37064525 | C34: =C19*(1+$O$16) -> 24565267 | D34: =B34+C34 -> 61629792 | E34: =E19*(1+$O$17) -> 24399050 | F34: =F19*(1+$O$18) -> 17877320 | G34: =P34+Q34 -> 42276370 | H34: =D34-G34 -> 19353422 | I34: =I33+H34 -> 3.3086363e+08 | J34: =B34-P34 -> 12665476 | K34: =C34-Q34 -> 6687946.5 | L34: =B34*32.3% -> 11971842 | M34: =C34*33.1% -> 8131103.3 | N34: =E34-L34 -> 12427208 | O34: =F34-M34 -> 9746217 | P34: =N34 + L34*(1-55%) + L34*55%*(1+$O$27) -> 24399050 | Q34: =O34 + M34*(1-55%) + M34*55%*(1+$O$27) -> 17877320
A35: =EDATE(A34,1) -> 46204 | B35: =B20*(1+$O$15) -> 39025158 | C35: =C20*(1+$O$16) -> 14404403 | D35: =B35+C35 -> 53429561 | E35: =E20*(1+$O$17) -> 25599837 | F35: =F20*(1+$O$18) -> 14639713 | G35: =P35+Q35 -> 40239550 | H35: =D35-G35 -> 13190011 | I35: =I34+H35 -> 3.4405364e+08 | J35: =B35-P35 -> 13425321 | K35: =C35-Q35 -> -235310.39 | L35: =B35*32.3% -> 12605126 | M35: =C35*33.1% -> 4767857.2 | N35: =E35-L35 -> 12994711 | O35: =F35-M35 -> 9871855.7 | P35: =N35 + L35*(1-55%) + L35*55%*(1+$O$27) -> 25599837 | Q35: =O35 + M35*(1-55%) + M35*55%*(1+$O$27) -> 14639713
A36: =EDATE(A35,1) -> 46235 | B36: =B21*(1+$O$15) -> 37987103 | C36: =C21*(1+$O$16) -> 25944300 | D36: =B36+C36 -> 63931403 | E36: =E21*(1+$O$17) -> 24634232 | F36: =F21*(1+$O$18) -> 18205854 | G36: =P36+Q36 -> 42840086 | H36: =D36-G36 -> 21091317 | I36: =I35+H36 -> 3.6514495e+08 | J36: =B36-P36 -> 13352871 | K36: =C36-Q36 -> 7738446.1 | L36: =B36*32.3% -> 12269834 | M36: =C36*33.1% -> 8587563.2 | N36: =E36-L36 -> 12364398 | O36: =F36-M36 -> 9618290.5 | P36: =N36 + L36*(1-55%) + L36*55%*(1+$O$27) -> 24634232 | Q36: =O36 + M36*(1-55%) + M36*55%*(1+$O$27) -> 18205854
A37: =EDATE(A36,1) -> 46266 | B37: =B22*(1+$O$15) -> 39379041 | C37: =C22*(1+$O$16) -> 25386370 | D37: =B37+C37 -> 64765411 | E37: =E22*(1+$O$17) -> 25236887 | F37: =F22*(1+$O$18) -> 19347951 | G37: =P37+Q37 -> 44584838 | H37: =D37-G37 -> 20180573 | I37: =I36+H37 -> 3.8532553e+08 | J37: =B37-P37 -> 14142153 | K37: =C37-Q37 -> 6038419.3 | L37: =B37*32.3% -> 12719430 | M37: =C37*33.1% -> 8402888.6 | N37: =E37-L37 -> 12517457 | O37: =F37-M37 -> 10945062 | P37: =N37 + L37*(1-55%) + L37*55%*(1+$O$27) -> 25236887 | Q37: =O37 + M37*(1-55%) + M37*55%*(1+$O$27) -> 19347951
A38: =EDATE(A37,1) -> 46296 | B38: =B23*(1+$O$15) -> 39429950 | C38: =C23*(1+$O$16) -> 26673000 | D38: =B38+C38 -> 66102950 | E38: =E23*(1+$O$17) -> 24899943 | F38: =F23*(1+$O$18) -> 18049356 | G38: =P38+Q38 -> 42949299 | H38: =D38-G38 -> 23153650 | I38: =I37+H38 -> 4.0847918e+08 | J38: =B38-P38 -> 14530007 | K38: =C38-Q38 -> 8623643.6 | L38: =B38*32.3% -> 12735874 | M38: =C38*33.1% -> 8828763 | N38: =E38-L38 -> 12164069 | O38: =F38-M38 -> 9220593.4 | P38: =N38 + L38*(1-55%) + L38*55%*(1+$O$27) -> 24899943 | Q38: =O38 + M38*(1-55%) + M38*55%*(1+$O$27) -> 18049356
A39: =EDATE(A38,1) -> 46327 | B39: =B24*(1+$O$15) -> 38127414 | C39: =C24*(1+$O$16) -> 26429710 | D39: =B39+C39 -> 64557124 | E39: =E24*(1+$O$17) -> 25291160 | F39: =F24*(1+$O$18) -> 17552117 | G39: =P39+Q39 -> 42843277 | H39: =D39-G39 -> 21713848 | I39: =I38+H39 -> 4.3019303e+08 | J39: =B39-P39 -> 12836254 | K39: =C39-Q39 -> 8877593.3 | L39: =B39*32.3% -> 12315155 | M39: =C39*33.1% -> 8748234 | N39: =E39-L39 -> 12976005 | O39: =F39-M39 -> 8803882.7 | P39: =N39 + L39*(1-55%) + L39*55%*(1+$O$27) -> 25291160 | Q39: =O39 + M39*(1-55%) + M39*55%*(1+$O$27) -> 17552117
A40: =EDATE(A39,1) -> 46357 | B40: =B25*(1+$O$15) -> 49539811 | C40: =C25*(1+$O$16) -> 27138526 | D40: =B40+C40 -> 76678337 | E40: =E25*(1+$O$17) -> 29270040 | F40: =F25*(1+$O$18) -> 19230301 | G40: =P40+Q40 -> 48500341 | H40: =D40-G40 -> 28177997 | I40: =I39+H40 -> 4.5837102e+08 | J40: =B40-P40 -> 20269771 | K40: =C40-Q40 -> 7908225.3 | L40: =B40*32.3% -> 16001359 | M40: =C40*33.1% -> 8982852.1 | N40: =E40-L40 -> 13268681 | O40: =F40-M40 -> 10247449 | P40: =N40 + L40*(1-55%) + L40*55%*(1+$O$27) -> 29270040 | Q40: =O40 + M40*(1-55%) + M40*55%*(1+$O$27) -> 19230301
B43: Dec 2026 Ending Cash | C43: 2026 Average Monthly Margin
...

Sheet New_Outlet_Scenario
A1: New Location | B1: D
A2: Start Month | B2: 1
A3: Mature Revenue Reference | B3: =AVERAGE(Projection!C20:C25) -> 20800333
A5: Months Since Opening | B5: Ramp-up C | C5: Ramp-up D | E5: Month # | F5: Months Since Opening | G5: Ramp-up % | H5: New Outlet Revenue | I5: New Raw Materials | J5: Operating Cost | K5: Capex | L5: Net Cash New Outlet | M5: Combined Ending Cash
A6: 1 | B6: 0.5 | C6: 0.3 | E6: 1 | F6: =IF(OR($B$1="None",$B$2="",E6<$B$2),0,E6-$B$2+1) -> 1 | G6: =IF(F6=0,0,IF($B$1="C", VLOOKUP(MIN(F6,12),$A$6:$C$17,2,FALSE),IF($B$1="D",VLOOKUP(MIN(F6,12),$A$6:$C$17,3,FALSE),0))) -> 0.3 | H6: =G6*$B$3 -> 6240100 | I6: =H6*33.1% -> 2065473.1 | J6: =IF(F6>=1,5800000,0) -> 5800000 | K6: =IF(E6 = $B$2, IF($B$1="C",134000000,IF($B$1="D",92000000,0)),0) -> 92000000 | L6: =H6-I6-J6-K6 -> -93625373 | M6: =Projection!I25+Projection!H29+L6 -> 1.5197185e+08
A7: 2 | B7: 0.65 | C7: 0.42 | E7: =E6+1 -> 2 | F7: =IF(OR($B$1="None",$B$2="",E7<$B$2),0,E7-$B$2+1) -> 2 | G7: =IF(F7=0,0,IF($B$1="C", VLOOKUP(MIN(F7,12),$A$6:$C$17,2,FALSE),IF($B$1="D",VLOOKUP(MIN(F7,12),$A$6:$C$17,3,FALSE),0))) -> 0.42 | H7: =G7*$B$3 -> 8736140 | I7: =H7*33.1% -> 2891662.3 | J7: =IF(F7>=1,5800000,0) -> 5800000 | K7: =IF(E7 = $B$2, IF($B$1="C",134000000,IF($B$1="D",92000000,0)),0) -> 0 | L7: =H7-I7-J7-K7 -> 44477.66 | M7: =M6+Projection!H30+L7 -> 1.6535316e+08
A8: 3 | B8: 0.78 | C8: 0.55 | E8: =E7+1 -> 3 | F8: =IF(OR($B$1="None",$B$2="",E8<$B$2),0,E8-$B$2+1) -> 3 | G8: =IF(F8=0,0,IF($B$1="C", VLOOKUP(MIN(F8,12),$A$6:$C$17,2,FALSE),IF($B$1="D",VLOOKUP(MIN(F8,12),$A$6:$C$17,3,FALSE),0))) -> 0.55 | H8: =G8*$B$3 -> 11440183 | I8: =H8*33.1% -> 3786700.7 | J8: =IF(F8>=1,5800000,0) -> 5800000 | K8: =IF(E8 = $B$2, IF($B$1="C",134000000,IF($B$1="D",92000000,0)),0) -> 0 | L8: =H8-I8-J8-K8 -> 1853482.7 | M8: =M7+Projection!H31+L8 -> 1.8638194e+08
A9: 4 | B9: 0.88 | C9: 0.68 | E9: =E8+1 -> 4 | F9: =IF(OR($B$1="None",$B$2="",E9<$B$2),0,E9-$B$2+1) -> 4 | G9: =IF(F9=0,0,IF($B$1="C", VLOOKUP(MIN(F9,12),$A$6:$C$17,2,FALSE),IF($B$1="D",VLOOKUP(MIN(F9,12),$A$6:$C$17,3,FALSE),0))) -> 0.68 | H9: =G9*$B$3 -> 14144227 | I9: =H9*33.1% -> 4681739 | J9: =IF(F9>=1,5800000,0) -> 5800000 | K9: =IF(E9 = $B$2, IF($B$1="C",134000000,IF($B$1="D",92000000,0)),0) -> 0 | L9: =H9-I9-J9-K9 -> 3662487.6 | M9: =M8+Projection!H32+L9 -> 2.0713732e+08
A10: 5 | B10: 0.95 | C10: 0.8 | E10: =E9+1 -> 5 | F10: =IF(OR($B$1="None",$B$2="",E10<$B$2),0,E10-$B$2+1) -> 5 | G10: =IF(F10=0,0,IF($B$1="C", VLOOKUP(MIN(F10,12),$A$6:$C$17,2,FALSE),IF($B$1="D",VLOOKUP(MIN(F10,12),$A$6:$C$17,3,FALSE),0))) -> 0.8 | H10: =G10*$B$3 -> 16640267 | I10: =H10*33.1% -> 5507928.3 | J10: =IF(F10>=1,5800000,0) -> 5800000 | K10: =IF(E10 = $B$2, IF($B$1="C",134000000,IF($B$1="D",92000000,0)),0) -> 0 | L10: =H10-I10-J10-K10 -> 5332338.4 | M10: =M9+Projection!H33+L10 -> 2.2877762e+08
A11: 6 | B11: 1 | C11: 0.9 | E11: =E10+1 -> 6 | F11: =IF(OR($B$1="None",$B$2="",E11<$B$2),0,E11-$B$2+1) -> 6 | G11: =IF(F11=0,0,IF($B$1="C", VLOOKUP(MIN(F11,12),$A$6:$C$17,2,FALSE),IF($B$1="D",VLOOKUP(MIN(F11,12),$A$6:$C$17,3,FALSE),0))) -> 0.9 | H11: =G11*$B$3 -> 18720300 | I11: =H11*33.1% -> 6196419.3 | J11: =IF(F11>=1,5800000,0) -> 5800000 | K11: =IF(E11 = $B$2, IF($B$1="C",134000000,IF($B$1="D",92000000,0)),0) -> 0 | L11: =H11-I11-J11-K11 -> 6723880.7 | M11: =M10+Projection!H34+L11 -> 2.5485492e+08
A12: 7 | B12: 1 | C12: 1 | E12: =E11+1 -> 7 | F12: =IF(OR($B$1="None",$B$2="",E12<$B$2),0,E12-$B$2+1) -> 7 | G12: =IF(F12=0,0,IF($B$1="C", VLOOKUP(MIN(F12,12),$A$6:$C$17,2,FALSE),IF($B$1="D",VLOOKUP(MIN(F12,12),$A$6:$C$17,3,FALSE),0))) -> 1 | H12: =G12*$B$3 -> 20800333 | I12: =H12*33.1% -> 6884910.3 | J12: =IF(F12>=1,5800000,0) -> 5800000 | K12: =IF(E12 = $B$2, IF($B$1="C",134000000,IF($B$1="D",92000000,0)),0) -> 0 | L12: =H12-I12-J12-K12 -> 8115423 | M12: =M11+Projection!H35+L12 -> 2.7616035e+08
A13: 8 | B13: 1 | C13: 1 | E13: =E12+1 -> 8 | F13: =IF(OR($B$1="None",$B$2="",E13<$B$2),0,E13-$B$2+1) -> 8 | G13: =IF(F13=0,0,IF($B$1="C", VLOOKUP(MIN(F13,12),$A$6:$C$17,2,FALSE),IF($B$1="D",VLOOKUP(MIN(F13,12),$A$6:$C$17,3,FALSE),0))) -> 1 | H13: =G13*$B$3 -> 20800333 | I13: =H13*33.1% -> 6884910.3 | J13: =IF(F13>=1,5800000,0) -> 5800000 | K13: =IF(E13 = $B$2, IF($B$1="C",134000000,IF($B$1="D",92000000,0)),0) -> 0 | L13: =H13-I13-J13-K13 -> 8115423 | M13: =M12+Projection!H36+L13 -> 3.0536709e+08
A14: 9 | B14: 1 | C14: 1 | E14: =E13+1 -> 9 | F14: =IF(OR($B$1="None",$B$2="",E14<$B$2),0,E14-$B$2+1) -> 9 | G14: =IF(F14=0,0,IF($B$1="C", VLOOKUP(MIN(F14,12),$A$6:$C$17,2,FALSE),IF($B$1="D",VLOOKUP(MIN(F14,12),$A$6:$C$17,3,FALSE),0))) -> 1 | H14: =G14*$B$3 -> 20800333 | I14: =H14*33.1% -> 6884910.3 | J14: =IF(F14>=1,5800000,0) -> 5800000 | K14: =IF(E14 = $B$2, IF($B$1="C",134000000,IF($B$1="D",92000000,0)),0) -> 0 | L14: =H14-I14-J14-K14 -> 8115423 | M14: =M13+Projection!H37+L14 -> 3.3366309e+08
A15: 10 | B15: 1 | C15: 1 | E15: =E14+1 -> 10 | F15: =IF(OR($B$1="None",$B$2="",E15<$B$2),0,E15-$B$2+1) -> 10 | G15: =IF(F15=0,0,IF($B$1="C", VLOOKUP(MIN(F15,12),$A$6:$C$17,2,FALSE),IF($B$1="D",VLOOKUP(MIN(F15,12),$A$6:$C$17,3,FALSE),0))) -> 1 | H15: =G15*$B$3 -> 20800333 | I15: =H15*33.1% -> 6884910.3 | J15: =IF(F15>=1,5800000,0) -> 5800000 | K15: =IF(E15 = $B$2, IF($B$1="C",134000000,IF($B$1="D",92000000,0)),0) -> 0 | L15: =H15-I15-J15-K15 -> 8115423 | M15: =M14+Projection!H38+L15 -> 3.6493216e+08
A16: 11 | B16: 1 | C16: 1 | E16: =E15+1 -> 11 | F16: =IF(OR($B$1="None",$B$2="",E16<$B$2),0,E16-$B$2+1) -> 11 | G16: =IF(F16=0,0,IF($B$1="C", VLOOKUP(MIN(F16,12),$A$6:$C$17,2,FALSE),IF($B$1="D",VLOOKUP(MIN(F16,12),$A$6:$C$17,3,FALSE),0))) -> 1 | H16: =G16*$B$3 -> 20800333 | I16: =H16*33.1% -> 6884910.3 | J16: =IF(F16>=1,5800000,0) -> 5800000 | K16: =IF(E16 = $B$2, IF($B$1="C",134000000,IF($B$1="D",92000000,0)),0) -> 0 | L16: =H16-I16-J16-K16 -> 8115423 | M16: =M15+Projection!H39+L16 -> 3.9476143e+08
A17: 12 | B17: 1 | C17: 1 | E17: =E16+1 -> 12 | F17: =IF(OR($B$1="None",$B$2="",E17<$B$2),0,E17-$B$2+1) -> 12 | G17: =IF(F17=0,0,IF($B$1="C", VLOOKUP(MIN(F17,12),$A$6:$C$17,2,FALSE),IF($B$1="D",VLOOKUP(MIN(F17,12),$A$6:$C$17,3,FALSE),0))) -> 1 | H17: =G17*$B$3 -> 20800333 | I17: =H17*33.1% -> 6884910.3 | J17: =IF(F17>=1,5800000,0) -> 5800000 | K17: =IF(E17 = $B$2, IF($B$1="C",134000000,IF($B$1="D",92000000,0)),0) -> 0 | L17: =H17-I17-J17-K17 -> 8115423 | M17: =M16+Projection!H40+L17 -> 4.3105485e+08
E21: Monthly Fixed Costs (2025 average): | H21: =(AVERAGE(Projection!E14:E25)-32.3%*AVERAGE(Projection!B14:B25))+(AVERAGE(Projection!F14:F25)-33.1%*AVERAGE(Projection!C14:C25)) -> 21565993
E22: Minimum Cash Reserve Target (4 months): | H22: =H21*4 -> 86263974
A24: None
A25: C
A26: D

Sheet Scenario Summary
B2: Scenario Summary
D3: Current Values: | E3: No New Outlet | F3: Location C - Month 1 | G3: Location C - Month 4 | H3: Location D - Month 1 | I3: Location D - Month 4
E4: Created by Admin on 9/27/2026 | F4: Created by Admin on 9/27/2026 | G4: Created by Admin on 9/27/2026 | H4: Created by Admin on 9/27/2026 | I4: Created by Admin on 9/27/2026
B5: Changing Cells:
C6: $B$1 | D6: None | E6: None | F6: C | G6: C | H6: D | I6: D
C7: $B$2 | D7: 1 | E7: 1 | F7: 1 | G7: 4 | H7: 1 | I7: 4
B8: Result Cells:
C9: $M$17 | D9: 4.5837102e+08 | E9: 4.5837102e+08 | F9: 4.0450097e+08 | G9: 3.801547e+08 | H9: 4.3105485e+08 | I9: 4.0670858e+08
B10: Notes: Current Values column represents values of changing cells at
B11: time Scenario Summary Report was created. Changing cells for each
B12: scenario are highlighted in gray.
